<mujoco model="humanoid">

  <statistic extent="2" center="0 0 1"/>

  <option timestep="0.00555"/>
  <contact>
    <exclude body1="pelvis" body2="upper_waists"/>
    <exclude body1="upper_waists" body2="lower_waists"/>
    <exclude body1="pelvis" body2="lower_waists"/>
  </contact>

  <default>
    <motor ctrlrange="-1 1" ctrllimited="true"/>
    <default class="body">
      <geom type="capsule" condim="1" friction="1.0 0.05 0.05" solimp=".9 .99 .003" solref=".015 1"/>
      <joint type="hinge" damping="0.1" stiffness="5" armature=".007" limited="true" solimplimit="0 .99 .01"/>
      <site size=".04" group="3"/>
      <default class="force-torque">
        <site type="box" size=".01 .01 .02" rgba="1 0 0 1" />
      </default>
      <default class="touch">
        <site type="capsule" rgba="0 0 1 .3"/>
      </default>
    </default>
  </default>
  
      <asset>
        <mesh name="base_link" file="base_link.STL"/>
        <mesh name="waist_yaw_link" file="waist_yaw_link.STL"/>
        <mesh name="waist_pitch_link" file="waist_pitch_link.STL"/>
        <mesh name="body" file="body.STL"/>
        <mesh name="neck_yaw_link" file="neck_yaw_link.STL"/>
        <mesh name="head" file="head.STL"/>
        <mesh name="left_shoulder_pitch_link" file="left_shoulder_pitch_link.STL"/>
        <mesh name="left_shoulder_roll_link" file="left_shoulder_roll_link.STL"/>
        <mesh name="left_shoulder_yaw_link" file="left_shoulder_yaw_link.STL"/>
        <mesh name="left_elbow_pitch_link" file="left_elbow_pitch_link.STL"/>
        <mesh name="left_elbow_yaw_link" file="left_elbow_yaw_link.STL"/>
        <mesh name="left_elbow_roll_link" file="left_elbow_roll_link.STL"/>
        <mesh name="left_wrist_pitch_link" file="left_wrist_pitch_link.STL"/>
        <mesh name="right_shoulder_pitch_link" file="right_shoulder_pitch_link.STL"/>
        <mesh name="right_shoulder_roll_link" file="right_shoulder_roll_link.STL"/>
        <mesh name="right_shoulder_yaw_link" file="right_shoulder_yaw_link.STL"/>
        <mesh name="right_elbow_pitch_link" file="right_elbow_pitch_link.STL"/>
        <mesh name="right_elbow_yaw_link" file="right_elbow_yaw_link.STL"/>
        <mesh name="right_elbow_roll_link" file="right_elbow_roll_link.STL"/>
        <mesh name="right_wrist_pitch_link" file="right_wrist_pitch_link.STL"/>
        <mesh name="left_hip_pitch_link" file="left_hip_pitch_link.STL"/>
        <mesh name="left_hip_roll_link" file="left_hip_roll_link.STL"/>
        <mesh name="left_hip_yaw_link" file="left_hip_yaw_link.STL"/>
        <mesh name="left_knee_link" file="left_knee_link.STL"/>
        <mesh name="left_ankle_pitch_link" file="left_ankle_pitch_link.STL"/>
        <mesh name="left_ankle_roll_link" file="left_ankle_roll_link.STL"/>
        <mesh name="right_hip_pitch_link" file="right_hip_pitch_link.STL"/>
        <mesh name="right_hip_roll_link" file="right_hip_roll_link.STL"/>
        <mesh name="right_hip_yaw_link" file="right_hip_yaw_link.STL"/>
        <mesh name="right_knee_link" file="right_knee_link.STL"/>
        <mesh name="right_ankle_pitch_link" file="right_ankle_pitch_link.STL"/>
        <mesh name="right_ankle_roll_link" file="right_ankle_roll_link.STL"/>
      </asset>

  <worldbody>
    <geom name="floor" type="plane" conaffinity="1" size="100 100 .2"/>
    <!-- <body name="pelvis" pos="0 0 1" childclass="body"> -->
    
    <body name="pelvis" pos="0 0 1" childclass="body">
      <!--freejoint name="root"/-->
      <!--修改需注意 geom需要 pos quat type mesh rgba/-->
      <!--site name与传感器有关无需更改-->
      <site name="root" class="force-torque"/>
      <!-- <geom name="pelvis" type="sphere" pos="0 0 0.07" size=".09" density="2226"/> -->
      <geom name="pelvis" type="mesh" mesh="base_link" rgba="1 1 1 1"/>
      <!-- <geom name="upper_waist" type="sphere" pos="0 0 0.205" size="0.07" density="2226"/> -->
      <!--<geom name="upper_waist" type="mesh" pos="0 0 0.12421"  mesh="waist_yaw_link" rgba="1 1 1 1"/>-->
      <!--<geom name="lower_waist" type="mesh" pos="0 0 0.12421"  mesh="waist_pitch_link" rgba="1 1 1 1"/>-->
      <site name="pelvis" class="touch" type="sphere" pos="0 0 0.07" size="0.091"/>
      <!--<site name="upper_waist" class="touch" type="sphere" pos="0 0 0.205" size="0.071"/>-->
      
        <body name="upper_waists" >
          <geom name="upper_waists" type="mesh" mesh="waist_yaw_link" rgba="1 1 1 1"/>
          <site name="upper_waists" class="touch" type="sphere" pos="0 0 0.205" size="0.071"/>        
          <joint name="abdomen_z" pos="0 0 0" axis="0 0 1" range="-50 50" stiffness="600" damping="60" armature=".025"/> 
            <body name="lower_waists" pos="0 0 0.12421" >
               <geom name="lower_waists"  type="mesh"  mesh="waist_pitch_link" rgba="1 1 1 1"/>
               <joint name="abdomen_y" pos="0 0 0" axis="0 1 0" range="-60 90" stiffness="600" damping="60" armature=".025"/>
            </body>
        </body>
     

      <body name="torso" pos="0 0 0">
        <light name="top" pos="0 0 2" mode="trackcom"/>
        <camera name="back" pos="-3 0 1" xyaxes="0 -1 0 1 0 2" mode="trackcom"/>
        <camera name="side" pos="0 -3 1" xyaxes="1 0 0 0 1 2" mode="trackcom"/>
        <joint name="abdomen_x" pos="0 0 0" axis="1 0 0" range="-60 60" stiffness="600" damping="60" armature=".025"/>
        <!--<joint name="abdomen_y" pos="0 0 0" axis="0 1 0" range="-60 90" stiffness="600" damping="60" armature=".025"/>
        <joint name="abdomen_z" pos="0 0 0" axis="0 0 1" range="-50 50" stiffness="600" damping="60" armature=".025"/>-->
        <!--<geom name="torso" type="sphere" pos="0 0 0.12" size="0.11" density="1794" mesh="base_link"/>-->
        <geom name="torso" pos="0 0 0.12421" type="mesh" rgba="1 1 1 1" mesh="body"/>
        <site name="torso" class="touch" type="sphere" pos="0 0 0.12" size="0.111"/>


        <body name="head" pos="0 0.00050194 0.65" >
          <joint name="neck_x" axis="1 0 0" range="-50 50" stiffness="50" damping="5" armature=".017"/>
          <joint name="neck_y" pos="0 0 0.05" axis="0 1 0" range="-40 60" stiffness="50" damping="5" armature=".017"/>
          <geom name="neck_y"  quat="-3.67321e-06 1.41253e-10 -3.8455e-05 1" type="mesh" rgba="1 1 1 1" mesh="head"/>
          <joint name="neck_z" axis="0 0 1" range="-45 45" stiffness="50" damping="5" armature=".017"/>
          <geom name="neck_z"  quat="-3.67321e-06 1.41253e-10 -3.8455e-05 1" type="mesh" rgba="1 1 1 1" mesh="neck_yaw_link"/>
          <site name="head" class="touch" pos="0 0 0.175" type="sphere" size="0.103"/>
          <camera name="egocentric" pos=".103 0 0.175" xyaxes="0 -1 0 .1 0 1" fovy="80"/>
        </body>

        <body name="right_upper_arm" pos="0.0027488 -0.22547 0.51" quat="0.996198 -0.0871194 0 0">
          <inertial pos="0.0005757 0.045558 0.00017409" quat="-0.141101 0.677669 0.177814 0.699455" mass="0.7975" diaginertia="0.000394229 0.000373028 0.000337343"/>
          <joint name="right_shoulder_x" axis="1 0 0" range="-180 45" stiffness="200" damping="20" armature=".02"/>
          <geom name="right_shoulder_x" type="mesh" rgba="1 1 1 1" mesh="right_shoulder_roll_link"/>
          <joint name="right_shoulder_y" axis="0 1 0" range="-180 60" stiffness="200" damping="20" armature=".02"/>
          <geom name="right_shoulder_y" type="mesh" rgba="1 1 1 1" mesh="right_shoulder_pitch_link"/>
          <joint name="right_shoulder_z" axis="0 0 1"  range="-90 90" stiffness="200" damping="20" armature=".02"/>
          <geom name="right_shoulder_z" quat="0.707105 0 0 0.707108" type="mesh" rgba="1 1 1 1" mesh="right_shoulder_yaw_link"/>
          <site name="right_upper_arm" class="touch" pos="0 0 -0.14" size="0.046 0.1" zaxis="0 0 1"/>

          <body name="right_lower_arm" pos="-7.48636e-11 2.0381e-05 -0.265" quat="1 3.8455e-05 0 0">
            <inertial pos="0.00246224 0.00145778 -0.216566" quat="0.518356 0.00509404 -0.0175802 0.854969" mass="0.627587" diaginertia="0.00881444 0.00874751 0.000546322"/>
            <joint name="right_elbow" pos="0 0 0" axis="0 1 0" range="-160 0" stiffness="150" damping="15" armature=".015"/>
            <geom name="right_elbow" type="mesh" rgba="1 1 1 1" mesh="right_elbow_pitch_link"/>
            <geom pos="0 0 -0.151" quat="1 -3.8455e-05 0 0" type="mesh" rgba="1 1 1 1" mesh="right_elbow_yaw_link"/>
            <geom pos="0 0 -0.151" type="mesh" rgba="1 1 1 1" mesh="right_elbow_roll_link"/>
            <site name="right_lower_arm" class="touch" pos="0 0 -0.12" size="0.041 0.0685" zaxis="0 1 0"/>

            <body name="right_hand" pos="0 0 -0.235">
              <geom name="right_hand" type="mesh" rgba="1 1 1 1" mesh="right_wrist_pitch_link"/>
              <site name="right_hand" class="touch" type="sphere" size=".041"/>
            </body>
          </body>
        </body>

        <body name="left_upper_arm" pos="0.0027488 0.22453 0.51" quat="0.996198 0.0871194 0 0">
          <inertial pos="0.00057526 -0.045558 0.00017481" quat="0.140992 0.677632 -0.178029 0.699458" mass="0.7975" diaginertia="0.00039421 0.000373021 0.000337339"/>
          <joint name="left_shoulder_x" axis="1 0 0" range="-45 180" stiffness="200" damping="20" armature=".02"/>
          <geom name="left_shoulder_x" type="mesh" rgba="1 1 1 1" mesh="left_shoulder_roll_link"/>
          <joint name="left_shoulder_y" axis="0 1 0" range="-180 60" stiffness="200" damping="20" armature=".02"/>
          <geom name="left_shoulder_y" type="mesh" rgba="1 1 1 1" mesh="left_shoulder_pitch_link"/>
          <joint name="left_shoulder_z" axis="0 0 1"  range="-90 90" stiffness="200" damping="20" armature=".02"/>
          <geom name="left_shoulder_z" quat="1 -3.8455e-05 0 0" type="mesh" rgba="1 1 1 1" mesh="left_shoulder_yaw_link"/>
          <site name="left_upper_arm" class="touch" pos="0 0 -0.14" size="0.046 0.1" zaxis="0 0 1"/>

          <body name="left_lower_arm" pos="0 -2.03811e-05 -0.265" quat="1 -3.8455e-05 0 0">
            <inertial pos="0.00233075 -0.00156548 -0.216552" quat="0.876335 -0.0179255 0.0050715 0.481342" mass="0.62762" diaginertia="0.00881688 0.00874569 0.000546268"/>
            <joint name="left_elbow" axis="0 1 0" range="-160 0" stiffness="150" damping="15" armature=".015"/>
            <geom name="left_lower_arm" type="mesh" rgba="1 1 1 1" mesh="left_elbow_pitch_link"/>
            <geom pos="0 0 -0.151" type="mesh" rgba="1 1 1 1" mesh="left_elbow_yaw_link"/>
            <geom pos="0 0 -0.151" quat="1 3.8455e-05 0 0" type="mesh" rgba="1 1 1 1" mesh="left_elbow_roll_link"/>
            <site name="left_lower_arm" class="touch" pos="0 0 -0.1" size="0.041 0.0685" zaxis="0 0 1"/>

            <body name="left_hand" pos="0 6.46044e-06 -0.235">
              <geom name="left_hand"  type="mesh" rgba="1 1 1 1" mesh="left_wrist_pitch_link"/>
              <site name="left_hand" class="touch" type="sphere" size=".041"/>
            </body>
          </body>
        </body>
      </body>

      <body name="right_thigh" pos="0 -0.124887 0">
        <inertial pos="-0.049029 3.537e-08 -3.7221e-08" quat="0.499999 0.500001 -0.49999 0.50001" mass="0.74535" diaginertia="0.001863 0.0013962 0.0013392"/>
        <joint name="right_hip_y" axis="0 1 0" range="-140 60" stiffness="300" damping="30" armature=".02"/>
        <geom name="right_hip_y" type="mesh" rgba="1 1 1 1" mesh="right_hip_pitch_link"/>
        <joint name="right_hip_x" axis="1 0 0" range="-60 15" stiffness="300" damping="30" armature=".02"/>
        <geom name="right_hip_x" type="mesh" rgba="1 1 1 1" mesh="right_hip_roll_link"/>
        <joint name="right_hip_z" axis="0 0 1" range="-60 35" stiffness="300" damping="30" armature=".02"/>
        <geom name="right_hip_z"  quat="0.707105 0 0 0.707108" type="mesh" rgba="1 1 1 1" mesh="right_hip_yaw_link"/>
        <site name="right_thigh" class="touch" pos="0 0 -0.21" size="0.056 0.301" zaxis="0 0 -1"/>

        <body name="right_shin" pos="0 0 -0.42">
          <inertial pos="0.00163174 -3.06908e-05 -0.203316" quat="0.996251 -3.6809e-05 0.086509 -6.0467e-05" mass="4.74475" diaginertia="0.0526845 0.0511884 0.00647413"/>
          <site name="right_knee" class="force-torque" pos="0 0 0"/>
          <joint name="right_knee" pos="0 0 0" axis="0 1 0" range="0 160" stiffness="300" damping="30" armature=".02"/>
          <geom name="right_shin" type="mesh" rgba="1 1 1 1" mesh="right_knee_link"/>
          <site name="right_shin" class="touch" pos="0 0 -0.2" size="0.051 0.156" zaxis="0 0 -1"/>

          <body name="right_foot" pos="0 0 -0.409870">
            <inertial pos="0.0481383 -2.14795e-06 -0.000114295" quat="0.507628 0.508177 -0.492634 0.491307" mass="0.251152" diaginertia="0.000358083 0.00031646 0.000274951"/>
            <site name="right_ankle" class="force-torque"/>
            <joint name="right_ankle_x" pos="0 0 0" axis="1 0 0" range="-30 30" stiffness="200" damping="20" armature=".01"/>
            <geom name="right_ankle_x" type="mesh" rgba="1 1 1 1" mesh="right_ankle_roll_link"/>
            <joint name="right_ankle_y" pos="0 0 0" axis="0 1 0" range="-55 55" stiffness="200" damping="20" armature=".01"/>
            <geom name="right_ankle_y" type="mesh" rgba="1 1 1 1" mesh="right_ankle_pitch_link"/>
            <joint name="right_ankle_z" pos="0 0 0" axis="0 0 1" range="-40 40" stiffness="200" damping="20" armature=".01"/>
            <site name="right_foot" class="touch" type="box" pos="0.045 0 -0.0225" size="0.0895 0.055 0.0285"/>
          </body>
        </body>
      </body>

      <body name="left_thigh" pos="0 0.11953 0">
        <inertial pos="-0.049029 3.537e-08 -3.7221e-08" quat="0.499999 0.500001 -0.49999 0.50001" mass="8.81659" diaginertia="0.001863 0.0013962 0.0013392"/>
        <site name="left_hip" class="force-torque"/>
        <joint name="left_hip_y" axis="0 1 0" range="-140 60" stiffness="300" damping="30" armature=".02"/>
        <geom name="left_hip_y" type="mesh" rgba="1 1 1 1" mesh="left_hip_pitch_link"/>
        <joint name="left_hip_x" axis="1 0 0" range="-15 60" stiffness="300" damping="30" armature=".02"/>
        <geom name="left_hip_x" type="mesh" rgba="1 1 1 1" mesh="left_hip_roll_link"/>
        <joint name="left_hip_z" axis="0 0 1" range="-35 60" stiffness="300" damping="30" armature=".02"/>
        <geom name="left_hip_z" quat="0.707105 0 0 0.707108" type="mesh" rgba="1 1 1 1" mesh="left_hip_yaw_link"/>
        <site name="left_thigh" class="touch" pos="0 0 -0.21" size="0.056 0.301" zaxis="0 0 -1"/>

        <body name="left_shin" pos="0 0 -0.42" >
          <inertial pos="0.00163174 -3.06908e-05 -0.203316" quat="0.996251 -3.6809e-05 0.086509 -6.0467e-05" mass="4.74475" diaginertia="0.0526845 0.0511884 0.00647413"/>
          <site name="left_knee" class="force-torque" pos="0 0 .02"/>
          <joint name="left_knee" pos="0 0 0" axis="0 1 0" range="0 160" stiffness="300" damping="30" armature=".02"/>
          <geom name="left_shin" type="mesh" rgba="1 1 1 1" mesh="left_knee_link"/>
          <site name="left_shin" class="touch" pos="0 0 -0.2" size="0.051 0.156" zaxis="0 0 -1"/>

          <body name="left_foot" pos="0 0 -0.41" quat="1 0 0 -3.993e-05">
            <inertial pos="0.0481383 2.03962e-06 -0.000114304" quat="0.508164 0.507643 -0.491303 0.492636" mass="1.4107" diaginertia="0.000358066 0.00031645 0.000274957"/>
            <site name="left_ankle" class="force-torque"/>
            <joint name="left_ankle_x" pos="0 0 0" axis="1 0 0" range="-30 30" stiffness="200" damping="20" armature=".01"/>
            <geom name="left_ankle_x" type="mesh" rgba="1 1 1 1" mesh="left_ankle_roll_link"/>
            <joint name="left_ankle_y" pos="0 0 0" axis="0 1 0" range="-55 55" stiffness="200" damping="20"
             armature=".01"/>
            <geom name="left_ankle_y" type="mesh" rgba="1 1 1 1" mesh="left_ankle_pitch_link"/>
            <joint name="left_ankle_z" pos="0 0 0" axis="0 0 1" range="-40 40" stiffness="200" damping="20" armature=".01"/>
            <site name="left_foot" class="touch" type="box" pos="0.045 0 -0.0225" size="0.0895 0.055 0.0285"/>
          </body>
        </body>
      </body>
    </body>
  </worldbody>

  <actuator>
    <motor name='abdomen_x'       gear='125' joint='abdomen_x'/>
    <motor name='abdomen_y'       gear='125' joint='abdomen_y'/>
    <motor name='abdomen_z'       gear='125' joint='abdomen_z'/>
    <motor name='neck_x'          gear='20' joint='neck_x'/>
    <motor name='neck_y'          gear='20' joint='neck_y'/>
    <motor name='neck_z'          gear='20' joint='neck_z'/>
    <motor name='right_shoulder_x' gear='70' joint='right_shoulder_x'/>
    <motor name='right_shoulder_y' gear='70' joint='right_shoulder_y'/>
    <motor name='right_shoulder_z' gear='70' joint='right_shoulder_z'/>
    <motor name='right_elbow'     gear='60' joint='right_elbow'/>
    <motor name='left_shoulder_x'  gear='70' joint='left_shoulder_x'/>
    <motor name='left_shoulder_y'  gear='70' joint='left_shoulder_y'/>
    <motor name='left_shoulder_z'  gear='70' joint='left_shoulder_z'/>
    <motor name='left_elbow'      gear='60' joint='left_elbow'/>
    <motor name='right_hip_x'     gear='125' joint='right_hip_x'/>
    <motor name='right_hip_z'     gear='125' joint='right_hip_z'/>
    <motor name='right_hip_y'     gear='125' joint='right_hip_y'/>
    <motor name='right_knee'      gear='100' joint='right_knee'/>
    <motor name='right_ankle_x'   gear='50' joint='right_ankle_x'/>
    <motor name='right_ankle_y'   gear='50' joint='right_ankle_y'/>
    <motor name='right_ankle_z'   gear='50' joint='right_ankle_z'/>
    <motor name='left_hip_x'      gear='125' joint='left_hip_x'/>
    <motor name='left_hip_z'      gear='125' joint='left_hip_z'/>
    <motor name='left_hip_y'      gear='125' joint='left_hip_y'/>
    <motor name='left_knee'       gear='100' joint='left_knee'/>
    <motor name='left_ankle_x'    gear='50' joint='left_ankle_x'/>
    <motor name='left_ankle_y'    gear='50' joint='left_ankle_y'/>
    <motor name='left_ankle_z'    gear='50' joint='left_ankle_z'/>
  </actuator>

  <sensor>
    <subtreelinvel name="pelvis_subtreelinvel" body="pelvis"/>
    <accelerometer name="root_accel"    site="root"/>
    <velocimeter name="root_vel"        site="root"/>
    <gyro name="root_gyro"              site="root"/>

    <force name="left_ankle_force"       site="left_ankle"/>
    <force name="right_ankle_force"      site="right_ankle"/>
    <force name="left_knee_force"        site="left_knee"/>
    <force name="right_knee_force"       site="right_knee"/>
    <force name="left_hip_force"         site="left_hip"/>
    <force name="right_hip_force"        site="right_hip"/>

    <torque name="left_ankle_torque"     site="left_ankle"/>
    <torque name="right_ankle_torque"    site="right_ankle"/>
    <torque name="left_knee_torque"      site="left_knee"/>
    <torque name="right_knee_torque"     site="right_knee"/>
    <torque name="left_hip_torque"       site="left_hip"/>
    <torque name="right_hip_torque"      site="right_hip"/>

    <touch name="pelvis_touch"           site="pelvis"/>
    <touch name="upper_waist_touch"      site="upper_waists"/>
    <touch name="torso_touch"            site="torso"/>
    <touch name="head_touch"             site="head"/>
    <touch name="right_upper_arm_touch"  site="right_upper_arm"/>
    <touch name="right_lower_arm_touch"  site="right_lower_arm"/>
    <touch name="right_hand_touch"       site="right_hand"/>
    <touch name="left_upper_arm_touch"   site="left_upper_arm"/>
    <touch name="left_lower_arm_touch"   site="left_lower_arm"/>
    <touch name="left_hand_touch"        site="left_hand"/>
    <touch name="right_thigh_touch"      site="right_thigh"/>
    <touch name="right_shin_touch"       site="right_shin"/>
    <touch name="right_foot_touch"       site="right_foot"/>
    <touch name="left_thigh_touch"       site="left_thigh"/>
    <touch name="left_shin_touch"        site="left_shin"/>
    <touch name="left_foot_touch"        site="left_foot"/>
  </sensor>

</mujoco>
