<mujoco model="B-20250522">
  <compiler angle="radian" meshdir="./meshes/"/>
  <default>
    <joint damping="0.5" armature="0.01" frictionloss="0.1"/>
    <default class="visual">
      <geom contype="0" conaffinity="0" group="0" density="0"/>
    </default>
    <default class="collision">
      <geom group="1"/>
    </default>
  </default>
  <asset>
    <mesh name="base" file="base.stl"/>
    <mesh name="waist_z" file="waist_z.stl"/>
    <mesh name="waist_x" file="waist_x.stl"/>
    <mesh name="body" file="body.stl"/>
    <mesh name="shoulder_y" file="shoulder_y.stl"/>
    <mesh name="shoulder_x" file="shoulder_x.stl"/>
    <mesh name="shoulder_z" file="shoulder_z.stl"/>
    <mesh name="elbow" file="elbow.stl"/>
    <mesh name="wrist_z" file="wrist_z.stl"/>
    <mesh name="wrist_y" file="wrist_y.stl"/>
    <mesh name="wrist_x" file="wrist_x.stl"/>
    <mesh name="hip_y" file="hip_y.stl"/>
    <mesh name="hip_x" file="hip_x.stl"/>
    <mesh name="hip_z" file="hip_z.stl"/>
    <mesh name="knee" file="knee.stl"/>
    <mesh name="ankle_y" file="ankle_y.stl"/>
    <mesh name="ankle_x" file="ankle_x.stl"/>
    <texture name="texplane" type="2d" builtin="checker" rgb1=".2 .3 .4" rgb2=".1 0.15 0.2" width="100" height="100"/>
    <material name="MatPlane" reflectance="0.5" texture="texplane" texrepeat="1 1" texuniform="true"/>
  </asset>

  <worldbody>
  <light cutoff="100" diffuse="1 1 1" dir="-0 0 -1.3" directional="true" exponent="1" pos="0 0 1.3" specular=".1 .1 .1" castshadow="false"/>
  <geom name="floor" friction="1 .1 .1" pos="0 0 0" size="500 500 0.125" type="plane" material="MatPlane" condim="3" conaffinity="1" contype="1" group="2" rgba="0.8 0.9 0.8 1"></geom>
  <body name="base_link" pos = "0 0 0.95">
    <freejoint name="root"/>
    <inertial pos="0.00036 -0.00001 0.01581" quat="1 0 0 0" mass="7.82975" diaginertia="0.04503 0.03128 0.03698"/>
    <geom type="mesh" rgba="0.75294 0.75294 0.75294 1" mesh="base" class="visual"/>
    <geom size="0.05 0.05" quat="0.707107 0.707107 0 0" type="cylinder" rgba="0.75294 0.75294 0.75294 1" class="collision"/>
    <body name="waist_yaw_link" pos="0 0 0.176">
      <inertial pos="0.00104 -0.00048 -0.01227" quat="0.441452 0.537958 0.459587 0.551816" mass="1.84403" diaginertia="0.00351223 0.00345809 0.00319968"/>
      <joint name="waist_yaw_joint" pos="0 0 0" axis="0 0 1" range="-3.6652 1.7453" actuatorfrcrange="-107 107"/>
      <geom type="mesh" rgba="0.75294 0.75294 0.75294 1" mesh="waist_z" class="visual"/>
      <geom size="0.065 0.015" pos="0 0 -0.07" type="cylinder" rgba="0.75294 0.75294 0.75294 1" class="collision"/>
      <body name="waist_roll_link">
        <inertial pos="-0.00258 0.00086 0.09228" quat="0.650708 0.0533482 0.0532416 0.755578" mass="3.40004" diaginertia="0.0130785 0.0127129 0.00866858"/>
        <joint name="waist_roll_joint" pos="0 0 0" axis="1 0 0" range="-0.7854 0.7854" actuatorfrcrange="-107 107"/>
        <geom type="mesh" rgba="0.75294 0.75294 0.75294 1" mesh="waist_x" class="visual"/>
        <geom size="0.03" pos="0 0 0" rgba="0.75294 0.75294 0.75294 1" class="collision"/>
        <body name="body" pos="0 0 0.114">
          <inertial pos="-0.03514 -0.00347 0.18093" quat="0.951381 -0.0192713 0.0416867 0.304573" mass="17.7226" diaginertia="0.280529 0.270458 0.158322"/>
          <joint name="waist_pitch_joint" pos="0 0 0" axis="0 1 0" range="-0.5236 1.5708" actuatorfrcrange="-413 413"/>
          <geom type="mesh" rgba="0.75294 0.75294 0.75294 1" mesh="body" class="visual"/>
          <geom size="0.1 0.1 0.12" pos="-0.025 0 0.125" type="box" rgba="0.75294 0.75294 0.75294 1" class="collision"/>
          <geom size="0.115 0.125 0.125" pos="-0.025 0 0.2" type="box" rgba="0.75294 0.75294 0.75294 1" class="collision"/>
          <geom size="0.05 0.05" pos="-0.029 0 0.35" type="cylinder" rgba="0.75294 0.75294 0.75294 1" class="collision"/>
          <geom size="0.1" pos="-0.01 0 0.48" rgba="0.75294 0.75294 0.75294 1" class="collision"/>
          <body name="left_shoulder_pitch_link" pos="-0.03 0.22635 0.225">
            <inertial pos="-0.00283 -0.01423 -0.00089" quat="0.54528 0.545862 -0.456723 0.442842" mass="1.82215" diaginertia="0.00402614 0.00386441 0.00252945"/>
            <joint name="left_shoulder_pitch_joint" pos="0 0 0" axis="0 1 0" range="-3.3161 1.5708" actuatorfrcrange="-107 107"/>
            <geom quat="0.707107 -0.707107 0 0" type="mesh" rgba="0.75294 0.75294 0.75294 1" mesh="shoulder_y" class="visual"/>
            <!-- <geom size="0.06 0.05" pos="0 -0.075 0" quat="0.707107 0.707107 0 0" type="cylinder" rgba="0.75294 0.75294 0.75294 1" class="collision"/> -->
            <body name="left_shoulder_roll_link">
              <inertial pos="0.00263 0 -0.05349" quat="0.680193 -0.193229 -0.193229 0.680193" mass="0.97689" diaginertia="0.0031 0.00274687 0.00214313"/>
              <joint name="left_shoulder_roll_joint" pos="0 0 0" axis="1 0 0" range="-0.43633 3.5779" actuatorfrcrange="-107 107"/>
              <geom type="mesh" rgba="0.75294 0.75294 0.75294 1" mesh="shoulder_x" class="visual"/>
              <geom size="0.055 0.04" pos="0 0 -0.09" type="cylinder" rgba="0.75294 0.75294 0.75294 1" class="collision"/>
              <geom size="0.055 0.055" quat="0.707107 0 0.707107 0" type="cylinder" rgba="0.75294 0.75294 0.75294 1" class="collision"/>
              <body name="left_shoulder_yaw_link" pos="0 0 -0.265">
                <inertial pos="-0.00978 -0.00126 0.09022" quat="0.999153 0.02114 -0.02756 -0.022052" mass="1.9789" diaginertia="0.00921773 0.00904872 0.00366355"/>
                <joint name="left_shoulder_yaw_joint" pos="0 0 0" axis="0 0 1" range="-2.9671 2.9671" actuatorfrcrange="-107 107"/>
                <geom type="mesh" rgba="0.75294 0.75294 0.75294 1" mesh="shoulder_z" class="visual"/>
                <geom size="0.055 0.03" pos="0 0 0.1" type="cylinder" rgba="0.75294 0.75294 0.75294 1" class="collision"/>
                <body name="left_elbow_link" quat="0.707107 0 -0.707107 0">
                  <inertial pos="-0.00024 0.00041 -0.02569" quat="0.952257 0.000711115 -0.0110603 0.305096" mass="2.12943" diaginertia="0.00532275 0.00525845 0.00288881"/>
                  <joint name="left_elbow_joint" pos="0 0 0" axis="0 1 0" range="-0.767945 1.74533" actuatorfrcrange="-107 107"/>
                  <geom type="mesh" rgba="0.75294 0.75294 0.75294 1" mesh="elbow" class="visual"/>
                  <geom size="0.055 0.055" quat="0.707107 0.707107 0 0" type="cylinder" rgba="0.75294 0.75294 0.75294 1" class="collision"/>
                  <!-- <geom size="0.045 0.075" pos="0 0 -0.05" type="cylinder" rgba="0.75294 0.75294 0.75294 1" class="collision"/> -->
                  <body name="left_wrist_yaw_link" pos="0 0 -0.16">
                    <inertial pos="3e-05 0.00439 0.00857" mass="0.79873" diaginertia="0.00085 0.0008 0.00072"/>
                    <joint name="left_wrist_yaw_joint" pos="0 0 0" axis="0 0 1" range="-2.9671 2.9671" actuatorfrcrange="-31 31"/>
                    <geom type="mesh" rgba="0.75294 0.75294 0.75294 1" mesh="wrist_z" class="visual"/>
                    <geom size="0.04 0.0475" quat="0.707107 0.707107 0 0" type="cylinder" rgba="0.75294 0.75294 0.75294 1" class="collision"/>
                    <body name="left_wrist_pitch_link">
                      <inertial pos="0.00237 -0.0016 -0.05688" quat="0.991666 -0.127747 0.0147584 0.00787091" mass="0.96977" diaginertia="0.00183063 0.00156879 0.00112059"/>
                      <joint name="left_wrist_pitch_joint" pos="0 0 0" axis="0 1 0" range="-1.5708 1.5708" actuatorfrcrange="-31 31"/>
                      <geom type="mesh" rgba="0.75294 0.75294 0.75294 1" mesh="wrist_y" class="visual"/>
                      <geom size="0.04 0.045" pos="0 0 -0.08" quat="0.707107 0 0.707107 0" type="cylinder" rgba="0.75294 0.75294 0.75294 1" class="collision"/>
                      <body name="left_wrist_roll_link" pos="0 0 -0.08">
                        <inertial pos="-0.00177 -0.00028 -0.05143" quat="0.706299 0.0337841 0.0337841 0.706299" mass="0.31088" diaginertia="0.00089 0.000702877 0.000387123"/>
                        <joint name="left_wrist_roll_joint" pos="0 0 0" axis="1 0 0" range="-1.5708 1.5708" actuatorfrcrange="-31 31"/>
                        <geom type="mesh" rgba="0.75294 0.75294 0.75294 1" mesh="wrist_x" class="visual"/>
                        <geom size="0.0425" pos="0 0 -0.0975" rgba="0.75294 0.75294 0.75294 1" class="collision"/>
                      </body>
                    </body>
                  </body>
                </body>
              </body>
            </body>
          </body>
          <body name="right_shoulder_pitch_link" pos="-0.03 -0.22635 0.225">
            <inertial pos="-0.00283 0.01423 0.00089" quat="0.537666 0.552004 -0.449614 0.451724" mass="1.82215" diaginertia="0.00402595 0.00386463 0.00252942"/>
            <joint name="right_shoulder_pitch_joint" pos="0 0 0" axis="0 1 0" range="-3.3161 1.5708" actuatorfrcrange="-107 107"/>
            <geom quat="0.707107 0.707107 0 0" type="mesh" rgba="0.75294 0.75294 0.75294 1" mesh="shoulder_y" class="visual"/>
            <!-- <geom size="0.06 0.05" pos="0 0.075 0" quat="0.707107 0.707107 0 0" type="cylinder" rgba="0.75294 0.75294 0.75294 1" class="collision"/> -->
            <body name="right_shoulder_roll_link">
              <inertial pos="0.00263 0 -0.05349" quat="0.680193 0.193229 0.193229 0.680193" mass="0.97689" diaginertia="0.0031 0.00274687 0.00214313"/>
              <joint name="right_shoulder_roll_joint" pos="0 0 0" axis="1 0 0" range="-3.5779 0.43633" actuatorfrcrange="-107 107"/>
              <geom type="mesh" rgba="0.75294 0.75294 0.75294 1" mesh="shoulder_x" class="visual"/>
              <geom size="0.055 0.04" pos="0 0 -0.09" type="cylinder" rgba="0.75294 0.75294 0.75294 1" class="collision"/>
              <geom size="0.055 0.055" quat="0.707107 0 0.707107 0" type="cylinder" rgba="0.75294 0.75294 0.75294 1" class="collision"/>
              <body name="right_shoulder_yaw_link" pos="0 0 -0.265">
                <inertial pos="-0.00978 -0.00126 0.09022" quat="0.999153 0.02114 -0.02756 -0.022052" mass="1.9789" diaginertia="0.00921773 0.00904872 0.00366355"/>
                <joint name="right_shoulder_yaw_joint" pos="0 0 0" axis="0 0 1" range="-2.9671 2.9671" actuatorfrcrange="-107 107"/>
                <geom type="mesh" rgba="0.752941 0.752941 0.752941 1" mesh="shoulder_z" class="visual"/>
                <geom size="0.055 0.03" pos="0 0 0.1" type="cylinder" rgba="0.752941 0.752941 0.752941 1" class="collision"/>
                <body name="right_elbow_link" quat="0.707107 0 -0.707107 0">
                  <inertial pos="-0.00024 0.00041 -0.02569" quat="0.952777 -0.00327104 -0.00984032 0.303495" mass="2.12943" diaginertia="0.0053223 0.00525873 0.00288896"/>
                  <joint name="right_elbow_joint" pos="0 0 0" axis="0 1 0" range="-0.767945 1.74533" actuatorfrcrange="-107 107"/>
                  <geom type="mesh" rgba="0.75294 0.75294 0.75294 1" mesh="elbow" class="visual"/>
                  <geom size="0.055 0.055" quat="0.707107 0.707107 0 0" type="cylinder" rgba="0.75294 0.75294 0.75294 1" class="collision"/>
                  <!-- <geom size="0.045 0.075" pos="0 0 -0.05" type="cylinder" rgba="0.75294 0.75294 0.75294 1" class="collision"/> -->
                  <body name="right_wrist_yaw_link" pos="0 0 -0.16">
                    <inertial pos="3e-05 0.00439 0.00857" quat="0.703487 0.0714533 -0.0714533 0.703487" mass="0.79873" diaginertia="0.000866158 0.00085 0.000713842"/>
                    <joint name="right_wrist_yaw_joint" pos="0 0 0" axis="0 0 1" range="-2.9671 2.9671" actuatorfrcrange="-31 31"/>
                    <geom type="mesh" rgba="0.75294 0.75294 0.75294 1" mesh="wrist_z" class="visual"/>
                    <geom size="0.04 0.0475" quat="0.707107 0.707107 0 0" type="cylinder" rgba="0.75294 0.75294 0.75294 1" class="collision"/>
                    <body name="right_wrist_pitch_link">
                      <inertial pos="0.00237 -0.0016 -0.05988" quat="0.991666 -0.127747 0.0147584 0.00787091" mass="0.96977" diaginertia="0.00183063 0.00156879 0.00112059"/>
                      <joint name="right_wrist_pitch_joint" pos="0 0 0" axis="0 1 0" range="-1.5708 1.5708" actuatorfrcrange="-31 31"/>
                      <geom type="mesh" rgba="0.75294 0.75294 0.75294 1" mesh="wrist_y" class="visual"/>
                      <geom size="0.04 0.045" pos="0 0 -0.08" quat="0.707107 0 0.707107 0" type="cylinder" rgba="0.75294 0.75294 0.75294 1" class="collision"/>
                      <body name="right_wrist_roll_link" pos="0 0 -0.08">
                        <inertial pos="-0.00177 -0.00028 -0.05143" quat="0.706299 0.0337841 0.0337841 0.706299" mass="0.31088" diaginertia="0.00089 0.000702877 0.000387123"/>
                        <joint name="right_wrist_roll_joint" pos="0 0 0" axis="1 0 0" range="-1.5708 1.5708" actuatorfrcrange="-31 31"/>
                        <geom type="mesh" rgba="0.75294 0.75294 0.75294 1" mesh="wrist_x" class="visual"/>
                        <geom size="0.0425" pos="0 0 -0.0975" rgba="0.75294 0.75294 0.75294 1" class="collision"/>
                      </body>
                    </body>
                  </body>
                </body>
              </body>
            </body>
          </body>
        </body>
      </body>
    </body>
    <body name="left_hip_pitch_link" pos="0 0.162 0">
      <inertial pos="-0.00121 -0.01442 -0.0003" quat="0.763796 0.642733 -0.0552737 -0.0213256" mass="1.89927" diaginertia="0.00366741 0.003418 0.00310459"/>
      <joint name="left_hip_pitch_joint" pos="0 0 0" axis="0 1 0" range="-2.7925 1.5708" actuatorfrcrange="-413 413"/>
      <geom quat="4.48966e-11 1 0 0" type="mesh" rgba="0.75294 0.75294 0.75294 1" mesh="hip_y" class="visual"/>
      <geom size="0.07 0.04" pos="0 -0.05 0" quat="0.707107 0.707107 0 0" type="cylinder" rgba="0.75294 0.75294 0.75294 1" class="collision"/>
      <geom size="0.06 0.0675" quat="0.707107 0 0.707107 0" type="cylinder" rgba="0.75294 0.75294 0.75294 1" class="collision"/>
      <body name="left_hip_roll_link">
        <inertial pos="0.00153 0.00791 -0.07015" quat="0.702158 -0.0477966 -0.0427511 0.709128" mass="1.75097" diaginertia="0.00954042 0.00724071 0.00534887"/>
        <joint name="left_hip_roll_joint" pos="0 0 0" axis="1 0 0" range="-0.43633 2.618" actuatorfrcrange="-107 107"/>
        <geom quat="4.48966e-11 0 0 1" type="mesh" rgba="0.75294 0.75294 0.75294 1" mesh="hip_x" class="visual"/>
        <!-- <geom size="0.07 0.04 0.075" pos="0 0 -0.05" type="box" rgba="0.75294 0.75294 0.75294 1" class="collision"/> -->
        <body name="left_hip_yaw_link" pos="0 0 -0.142">
          <inertial pos="-0.00126 0.00032 -0.04122" quat="0.999978 -0.000703661 0.00164653 0.00637947" mass="3.59517" diaginertia="0.0492207 0.0476398 0.0126795"/>
          <joint name="left_hip_yaw_joint" pos="0 0 0" axis="0 0 1" range="-0.5236 3.6652" actuatorfrcrange="-107 107"/>
          <geom type="mesh" rgba="0.75294 0.75294 0.75294 1" mesh="hip_z" class="visual"/>
          <geom size="0.06 0.10" pos="0 0 -0.06" type="cylinder" rgba="0.75294 0.75294 0.75294 1" class="collision"/>
          <body name="left_knee_link" pos="0 0 -0.278">
            <inertial pos="-0.00065 0.00024 -0.10231" quat="0.99888 0.002419 0.0146062 -0.0449355" mass="4.66882" diaginertia="0.0963486 0.0956174 0.00965401"/>
            <joint name="left_knee_joint" pos="0 0 0" axis="0 1 0" range="-0.17453 2.2" actuatorfrcrange="-413 413"/>
            <geom type="mesh" rgba="0.75294 0.75294 0.75294 1" mesh="knee" class="visual"/>
            <geom size="0.07 0.06" quat="0.707107 0.707107 0 0" type="cylinder" rgba="0.75294 0.75294 0.75294 1" class="collision"/>
            <geom size="0.055 0.15" pos="0 0 -0.2" type="cylinder" rgba="0.75294 0.75294 0.75294 1" class="collision"/>
            <body name="left_ankle_pitch_link" pos="0 0 -0.41">
              <inertial pos="0.00233 -0.00031 -0.00088" quat="0.147007 0.700314 0.0210594 0.698216" mass="1.4119" diaginertia="0.00191483 0.00182875 0.00171641"/>
              <joint name="left_ankle_pitch_joint" pos="0 0 0" axis="0 1 0" range="-1.0472 0.7854" actuatorfrcrange="-107 107"/>
              <geom type="mesh" rgba="0.75294 0.75294 0.75294 1" mesh="ankle_y" class="visual"/>
              <geom size="0.025 0.03" quat="0.707107 0.707107 0 0" type="cylinder" rgba="0.75294 0.75294 0.75294 1" class="collision"/>
              <body name="left_ankle_roll_link">
                <inertial pos="0.05253 8e-05 -0.0295" quat="0.480731 0.519412 0.515511 0.48307" mass="1.78979" diaginertia="0.01056 0.0104471 0.00311293"/>
                <joint name="left_ankle_roll_joint" pos="0 0 0" axis="1 0 0" range="-0.61087 0.61087" actuatorfrcrange="-31 31"/>
                <geom type="mesh" rgba="0.75294 0.75294 0.75294 1" mesh="ankle_x" class="visual"/>
                <geom size="0.13 0.055 0.01" pos="0.045 0 -0.06" type="box" rgba="0.75294 0.75294 0.75294 1" class="collision"/>
              </body>
            </body>
          </body>
        </body>
      </body>
    </body>
    <body name="right_hip_pitch_link" pos="0 -0.162 0">
      <inertial pos="0.00121 0.01442 -0.0003" quat="0.642733 0.763796 -0.0213256 -0.0552737" mass="1.89927" diaginertia="0.00366741 0.003418 0.00310459"/>
      <joint name="right_hip_pitch_joint" pos="0 0 0" axis="0 1 0" range="-2.7925 1.5708" actuatorfrcrange="-413 413"/>
      <geom type="mesh" rgba="1 1 1 1" mesh="hip_y" class="visual"/>
      <geom size="0.07 0.04" pos="0 0.05 0" quat="0.707107 0.707107 0 0" type="cylinder" rgba="1 1 1 1" class="collision"/>
      <geom size="0.06 0.0675" quat="0.707107 0 0.707107 0" type="cylinder" rgba="1 1 1 1" class="collision"/>
      <body name="right_hip_roll_link">
        <inertial pos="-0.00153 -0.00791 -0.07015" quat="0.702158 0.0477966 0.0427511 0.709128" mass="1.75097" diaginertia="0.00954042 0.00724071 0.00534887"/>
        <joint name="right_hip_roll_joint" pos="0 0 0" axis="1 0 0" range="-2.618 0.43633" actuatorfrcrange="-107 107"/>
        <geom type="mesh" rgba="0.75294 0.75294 0.75294 1" mesh="hip_x" class="visual"/>
        <!-- <geom size="0.07 0.04 0.075" pos="0 0 -0.05" type="box" rgba="0.75294 0.75294 0.75294 1" class="collision"/> -->
        <body name="right_hip_yaw_link" pos="0 0 -0.142">
          <inertial pos="-0.00126 0.00032 -0.04122" quat="0.999979 0.000726316 0.00163749 0.00627329" mass="3.59517" diaginertia="0.0492206 0.0476398 0.0126795"/>
          <joint name="right_hip_yaw_joint" pos="0 0 0" axis="0 0 1" range="-3.6652 0.5236" actuatorfrcrange="-107 107"/>
          <geom type="mesh" rgba="0.75294 0.75294 0.75294 1" mesh="hip_z" class="visual"/>
          <geom size="0.06 0.10" pos="0 0 -0.06" type="cylinder" rgba="0.75294 0.75294 0.75294 1" class="collision"/>
          <body name="right_knee_link" pos="0 0 -0.278">
            <inertial pos="-0.00065 0.00024 -0.10231" quat="0.99888 0.002419 0.0146062 -0.0449355" mass="4.66882" diaginertia="0.0963486 0.0956174 0.00965401"/>
            <joint name="right_knee_joint" pos="0 0 0" axis="0 1 0" range="-0.17453 2.2" actuatorfrcrange="-413 413"/>
            <geom type="mesh" rgba="0.75294 0.75294 0.75294 1" mesh="knee" class="visual"/>
            <geom size="0.07 0.06" quat="0.707107 0.707107 0 0" type="cylinder" rgba="0.75294 0.75294 0.75294 1" class="collision"/>
            <geom size="0.055 0.15" pos="0 0 -0.2" type="cylinder" rgba="0.75294 0.75294 0.75294 1" class="collision"/>
            <body name="right_ankle_pitch_link" pos="0 0 -0.41">
              <inertial pos="0.00233 -0.00031 0.00088" quat="0.137386 0.700402 -3.02034e-08 0.700402" mass="1.4119" diaginertia="0.00192392 0.00182 0.00171608"/>
              <joint name="right_ankle_pitch_joint" pos="0 0 0" axis="0 1 0" range="-1.0472 0.7854" actuatorfrcrange="-107 107"/>
              <geom type="mesh" rgba="0.75294 0.75294 0.75294 1" mesh="ankle_y" class="visual"/>
              <geom size="0.025 0.03" quat="0.707107 0.707107 0 0" type="cylinder" rgba="0.75294 0.75294 0.75294 1" class="collision"/>
              <body name="right_ankle_roll_link">
                <inertial pos="0.05253 8e-05 -0.0295" quat="0.480731 0.519412 0.515511 0.48307" mass="1.78979" diaginertia="0.01056 0.0104471 0.00311293"/>
                <joint name="right_ankle_roll_joint" pos="0 0 0" axis="1 0 0" range="-0.61087 0.61087" actuatorfrcrange="-31 31"/>
                <geom type="mesh" rgba="0.75294 0.75294 0.75294 1" mesh="ankle_x" class="visual"/>
                <geom size="0.13 0.055 0.01" pos="0.045 0 -0.06" type="box" rgba="0.75294 0.75294 0.75294 1" class="collision"/>
              </body>
            </body>
          </body>
        </body>
      </body>
    </body>
  </body>
  </worldbody>

  <actuator>
    <motor name='waist_yaw_joint' joint='waist_yaw_joint'/>
    <motor name='waist_roll_joint' joint='waist_roll_joint'/>
    <motor name='waist_pitch_joint' joint='waist_pitch_joint'/>

    <motor name='left_shoulder_pitch_joint' joint='left_shoulder_pitch_joint'/>
    <motor name='left_shoulder_roll_joint' joint='left_shoulder_roll_joint'/>
    <motor name='left_shoulder_yaw_joint' joint='left_shoulder_yaw_joint'/>
    <motor name='left_elbow_joint' joint='left_elbow_joint'/>
    <motor name='left_wrist_yaw_joint' joint='left_wrist_yaw_joint'/>
    <motor name='left_wrist_pitch_joint' joint='left_wrist_pitch_joint'/>
    <motor name='left_wrist_roll_joint' joint='left_wrist_roll_joint'/>

    <motor name='right_shoulder_pitch_joint' joint='right_shoulder_pitch_joint'/>
    <motor name='right_shoulder_roll_joint' joint='right_shoulder_roll_joint'/>
    <motor name='right_shoulder_yaw_joint' joint='right_shoulder_yaw_joint'/>
    <motor name='right_elbow_joint' joint='right_elbow_joint'/>
    <motor name='right_wrist_yaw_joint' joint='right_wrist_yaw_joint'/>
    <motor name='right_wrist_pitch_joint' joint='right_wrist_pitch_joint'/>
    <motor name='right_wrist_roll_joint' joint='right_wrist_roll_joint'/>

    <motor name='left_hip_pitch_joint' joint='left_hip_pitch_joint'/>
    <motor name='left_hip_roll_joint' joint='left_hip_roll_joint'/>
    <motor name='left_hip_yaw_joint' joint='left_hip_yaw_joint'/>
    <motor name='left_knee_joint' joint='left_knee_joint'/>
    <motor name='left_ankle_pitch_joint' joint='left_ankle_pitch_joint'/>
    <motor name='left_ankle_roll_joint' joint='left_ankle_roll_joint'/>

    <motor name='right_hip_pitch_joint' joint='right_hip_pitch_joint'/>
    <motor name='right_hip_roll_joint' joint='right_hip_roll_joint'/>
    <motor name='right_hip_yaw_joint' joint='right_hip_yaw_joint'/>
    <motor name='right_knee_joint' joint='right_knee_joint'/>
    <motor name='right_ankle_pitch_joint' joint='right_ankle_pitch_joint'/>
    <motor name='right_ankle_roll_joint' joint='right_ankle_roll_joint'/>

  </actuator>

</mujoco>
