<mujoco model="humanoid_K18"> <!-- walk run & backflip -->

  <statistic extent="2" center="0 0 1"/>

  <option timestep="0.00555"/>

  <default>
    <motor ctrlrange="-1 1" ctrllimited="true"/>
    <default class="body">
      <geom type="capsule" condim="1" friction="1.0 0.05 0.05" solimp=".9 .99 .003" solref=".015 1"/>
      <joint type="hinge" damping="0.1" stiffness="5" armature=".007" limited="true" solimplimit="0 .99 .01"/>
      <site size=".04" group="3"/>
      <default class="force-torque">
        <site type="box" size=".01 .01 .02" rgba="1 0 0 1" />
      </default>
      <default class="touch">
        <site type="capsule" rgba="0 0 1 .3"/>
      </default>
    </default>
  </default>

  <asset>
  	<texture name="texplane" type="2d" builtin="checker" rgb1=".2 .3 .4" rgb2=".1 0.15 0.2" width="512" height="512" mark="cross" markrgb=".8 .8 .8"/>
  	<material name="matplane" reflectance="0.3" texture="texplane" texrepeat="1 1" texuniform="true"/>
        <mesh name="TORSO" file="body.STL"/>
        <mesh name="base_link" file="base_link.STL"/>
        <mesh name="waist_yaw_link" file="waist_yaw_link.STL"/>
        <mesh name="waist_pitch_link" file="waist_pitch_link.STL"/>
        <mesh name="head" file="head.STL"/>
        <mesh name="neck_yaw_link" file="neck_yaw_link.STL"/>
        <mesh name="left_shoulder_pitch_link" file="left_shoulder_pitch_link.STL"/>
        <mesh name="left_shoulder_roll_link" file="left_shoulder_roll_link.STL"/>
        <mesh name="left_shoulder_yaw_link" file="left_shoulder_yaw_link.STL"/>
        <mesh name="right_shoulder_pitch_link" file="right_shoulder_pitch_link.STL"/>
        <mesh name="right_shoulder_roll_link" file="right_shoulder_roll_link.STL"/>
        <mesh name="right_shoulder_yaw_link" file="right_shoulder_yaw_link.STL"/>
        <mesh name="right_elbow_pitch_link" file="right_elbow_pitch_link.STL"/>
        <mesh name="right_elbow_yaw_link" file="right_elbow_yaw_link.STL"/>
        <mesh name="right_elbow_roll_link" file="right_elbow_roll_link.STL"/>
        <mesh name="right_wrist_pitch_link" file="right_wrist_pitch_link.STL"/>
        <mesh name="left_elbow_pitch_link" file="left_elbow_pitch_link.STL"/>
        <mesh name="left_elbow_yaw_link" file="left_elbow_yaw_link.STL"/>
        <mesh name="left_elbow_roll_link" file="left_elbow_roll_link.STL"/>
        <mesh name="left_wrist_pitch_link" file="left_wrist_pitch_link.STL"/>
        <mesh name="right_hip_pitch_link" file="right_hip_pitch_link.STL"/>
        <mesh name="right_hip_roll_link" file="right_hip_roll_link.STL"/>
        <mesh name="right_hip_yaw_link" file="right_hip_yaw_link.STL"/>
        <mesh name="right_knee_link" file="right_knee_link.STL"/>
        <mesh name="right_ankle_roll_link" file="right_ankle_roll_link.STL"/>
        <mesh name="right_ankle_pitch_link" file="right_ankle_pitch_link.STL"/>
        <mesh name="left_hip_pitch_link" file="left_hip_pitch_link.STL"/>
        <mesh name="left_hip_roll_link" file="left_hip_roll_link.STL"/>
        <mesh name="left_hip_yaw_link" file="left_hip_yaw_link.STL"/>
        <mesh name="left_knee_link" file="left_knee_link.STL"/>
        <mesh name="left_ankle_roll_link" file="left_ankle_roll_link.STL"/>
        <mesh name="left_ankle_pitch_link" file="left_ankle_pitch_link.STL"/>
    </asset>

  <worldbody>
    <geom name="floor" type="plane" conaffinity="1" size="100 100 .2"/><!--material="grid"-->
    <body name="pelvis" pos="0 0 1.1" childclass="body">
      <freejoint name="root"/>
      <inertial pos="0 0 0" quat="1 0 0 0" mass="1.958" diaginertia="0.00152876934955445 0.00071113482487 0.00128452784"/>
      <geom name="pelvis" type="mesh" pos="0 0 0.025" rgba="1 1 1 1" mesh="base_link"/>
      <geom name="waistyaw" type="mesh" pos="0 0 0.025" rgba="1 1 1 1" mesh="waist_yaw_link"/>
      <geom name="pelvis_vis" type="mesh" pos="0 0 0.025" rgba="1 1 1 1" mesh="base_link" contype="0" conaffinity="0"/>
      <geom name="waistyaw_vis" type="mesh" pos="0 0 0.025" rgba="1 1 1 1" mesh="waist_yaw_link" contype="0" conaffinity="0"/>
      <body name="torso" pos="0 0 0.336151">
        <inertial pos="0 0 0" quat="1 0 0 0" mass="28.128959" diaginertia="0.44277858 0.4617103 0.227623804"/>
        <light name="top" pos="0 0 2" mode="trackcom"/>
        <camera name="back" pos="-3 0 1" xyaxes="0 -1 0 1 0 2" mode="trackcom"/>
        <camera name="side" pos="0 -3 1" xyaxes="1 0 0 0 1 2" mode="trackcom"/>
        <joint name="abdomen_z" pos="0 0 -0.35" axis="0 0 1" range="-50 50" stiffness="600" damping="60" armature=".025"/>
        <joint name="abdomen_y" pos="0 0 -0.2" axis="0 1 0" range="-60 90" stiffness="600" damping="60" armature=".025"/>
        <joint name="abdomen_x" pos="0 0 -0.2" axis="1 0 0" range="-60 60" stiffness="600" damping="60" armature=".025"/>
        <geom name="upper_waist" type="mesh" pos="0 0 -0.2" rgba="1 1 1 1" mesh="waist_pitch_link"/>
        <geom name="upper_waist_vis" type="mesh" pos="0 0 0.15" rgba="1 1 1 1" mesh="waist_pitch_link" contype="0" conaffinity="0"/>
        <geom name="torso_vis" type="mesh" contype="0" conaffinity="0" pos="0 0 -0.2" rgba="1 1 1 1" mesh="TORSO"/>
        <geom name="torso" type="mesh" pos="0 0 -0.2" rgba="1 1 1 1" mesh="TORSO"/>
        <body name="head" pos="0 0 0.223894">
          <inertial pos="0 0 0" quat="1 0 0 0" mass="4.341" diaginertia="0.019131 0.021541 0.0149294"/>
          <joint name="neck_x" axis="1 0 0" range="-50 50" stiffness="50" damping="25" armature=".017"/>
          <joint name="neck_y" axis="0 1 0" range="-40 60" stiffness="50" damping="25" armature=".017"/>
          <joint name="neck_z" axis="0 0 1" range="-45 45" stiffness="50" damping="25" armature=".017"/>
          <geom name="head" type="mesh" pos="0 0 0.1" quat="0 0 0 1" rgba="1 1 1 1" mesh="head"/>
          <geom name="neckyaw" type="mesh" pos="0 0 0.1" rgba="1 1 1 1" mesh="neck_yaw_link"/>
          <geom name="head_vis" type="mesh" pos="0 0 0.1" quat="0 0 0 1" rgba="1 1 1 1" mesh="head" contype="0" conaffinity="0"/>
          <geom name="neckyaw_vis" type="mesh" pos="0 0 0.1" rgba="1 1 1 1" mesh="neck_yaw_link" contype="0" conaffinity="0"/>
        </body>

        <body name="right_upper_arm" pos="-0.02405 -0.27 0.20" quat="0.996198 -0.0871194 0 0">
          <inertial pos="-0.000491912 0.0360526 -0.0977407" quat="0.994445 -0.00133114 -0.000263131 -0.105246" mass="0.79574" diaginertia="0.00918927 0.00904548 0.00107071"/>
          <joint name="right_shoulder_x" axis="1 0 0" range="-180 45" stiffness="200" damping="20" armature=".02"/>
          <!-- <joint name="right_shoulder_y" axis="0 1 0" range="-180 60" stiffness="200" damping="20" armature=".02"/> -->
          <joint name="right_shoulder_z" axis="0 0 1"  range="-90 90" stiffness="200" damping="20" armature=".02"/>
          <geom name="right_upper_arm1" type="mesh" pos="0 0 0"  rgba="1 1 1 1" mesh="right_shoulder_pitch_link"/>
          <joint name="right_shoulder_y" axis="0 1 0" range="-180 60" stiffness="200" damping="20" armature=".02"/>
          <geom name="right_upper_arm2" pos="0 0 0" quat="0.996198 0.0871194 0 0" type="mesh" rgba="1 1 1 1" mesh="right_shoulder_roll_link"/>
          <geom name="right_upper_arm3" pos="0 0 0" quat="0.704417 0.0616026 -0.0616028 0.70442" type="mesh" rgba="1 1 1 1" mesh="right_shoulder_yaw_link"/>
          <geom name="right_upper_arm1_vis" type="mesh" pos="0 0 0"  rgba="1 1 1 1" mesh="right_shoulder_pitch_link" contype="0" conaffinity="0"/>
          <geom name="right_upper_arm2_vis" pos="0 0 0" quat="0.996198 0.0871194 0 0" type="mesh" rgba="1 1 1 1" mesh="right_shoulder_roll_link" contype="0" conaffinity="0"/>
          <geom name="right_upper_arm3_vis" pos="0 0 0" quat="0.704417 0.0616026 -0.0616028 0.70442" type="mesh" rgba="1 1 1 1" mesh="right_shoulder_yaw_link" contype="0" conaffinity="0"/>
          <site name="right_upper_arm" class="touch" pos="0 0 -0.14" size="0.046 0.1" zaxis="0 0 1"/>

          <body name="right_lower_arm" pos="0 0.0460178 -0.260974" quat="0.996195 0.0871577 0 0">
            <inertial pos="0.00246224 0.00145778 -0.216566" quat="0.518356 0.00509404 -0.0175802 0.854969" mass="0.627587" diaginertia="0.00881444 0.00874751 0.000546322"/>
            <joint name="right_elbow" axis="0 1 0" range="-160 0" stiffness="150" damping="15" armature=".015"/>
            <!-- <geom name="right_lower_arm" fromto="0 0 -0.0525 0 0 -0.1875" size="0.04" density="1056"/> -->
            <geom name="right_lower_arm1" type="mesh" rgba="1 1 1 1" mesh="right_elbow_pitch_link"/>
            <geom name="right_lower_arm2" pos="0 0 -0.151" quat="1 -3.8455e-05 0 0" type="mesh" rgba="1 1 1 1" mesh="right_elbow_yaw_link"/>
            <geom name="right_lower_arm3" pos="0 0 -0.151" quat="1 0 0 0" type="mesh" rgba="1 1 1 1" mesh="right_elbow_roll_link"/>
            <geom name="right_lower_arm1_vis" type="mesh" rgba="1 1 1 1" mesh="right_elbow_pitch_link" contype="0" conaffinity="0"/>
            <geom name="right_lower_arm2_vis" pos="0 0 -0.151" quat="1 -3.8455e-05 0 0" type="mesh" rgba="1 1 1 1" mesh="right_elbow_yaw_link" contype="0" conaffinity="0"/>
            <geom name="right_lower_arm3_vis" pos="0 0 -0.151" quat="1 0 0 0" type="mesh" rgba="1 1 1 1" mesh="right_elbow_roll_link" contype="0" conaffinity="0"/>
            <site name="right_lower_arm" class="touch" pos="0 0 -0.12" size="0.041 0.0685" zaxis="0 1 0"/>

            <body name="right_hand" pos="0 0 -0.235">
              <inertial pos="0 0 0" quat="0.518356 0.00509404 -0.0175802 0.854969" mass="0.31" diaginertia="0.000774 0.00082 0.0002681"/>
              <!-- <geom name="right_hand" type="sphere" size=".04" density="1865"/> -->
              <geom name="right_hand" pos="0 0 0" quat="1 0 0 0" type="mesh" rgba="1 1 1 1" mesh="right_wrist_pitch_link"/>
              <geom name="right_hand_vis" pos="0 0 0" quat="1 0 0 0" type="mesh" rgba="1 1 1 1" mesh="right_wrist_pitch_link" contype="0" conaffinity="0"/>
              <site name="right_hand" class="touch" type="sphere" size=".041"/>
            </body>
          </body>
        </body>

        <body name="left_upper_arm" pos="-0.02405 0.27 0.20" quat="0.996198 0.0871194 0 0">
          <inertial pos="-0.000491878 -0.0360532 -0.0977415" quat="0.994448 0.00132518 -0.000265861 0.10522" mass="0.79573" diaginertia="0.00918914 0.00904533 0.00107064"/>
          <joint name="left_shoulder_x" axis="1 0 0" range="-45 180" stiffness="200" damping="20" armature=".02"/>
          <joint name="left_shoulder_y" axis="0 1 0" range="-180 60" stiffness="200" damping="20" armature=".02"/>
          <joint name="left_shoulder_z" axis="0 0 1"  range="-90 90" stiffness="200" damping="20" armature=".02"/>
          <!-- <geom name="left_upper_arm" fromto="0 0 -0.05 0 0 -0.23" size="0.045" density="982"/> -->
          <geom name="left_upper_arm1" type="mesh" rgba="1 1 1 1" mesh="left_shoulder_pitch_link"/>
          <geom name="left_upper_arm2" pos="0 0 0" quat="0.996198 -0.0871194 0 0" type="mesh" rgba="1 1 1 1" mesh="left_shoulder_roll_link"/>
          <geom name="left_upper_arm3" quat="0.996195 -0.0871577 0 0" type="mesh" rgba="1 1 1 1" mesh="left_shoulder_yaw_link"/>
          <geom name="left_upper_arm1_vis" type="mesh" rgba="1 1 1 1" mesh="left_shoulder_pitch_link" contype="0" conaffinity="0"/>
          <geom name="left_upper_arm2_vis" pos="0 0 0" quat="0.996198 -0.0871194 0 0" type="mesh" rgba="1 1 1 1" mesh="left_shoulder_roll_link" contype="0" conaffinity="0"/>
          <geom name="left_upper_arm3_vis" quat="0.996195 -0.0871577 0 0" type="mesh" rgba="1 1 1 1" mesh="left_shoulder_yaw_link" contype="0" conaffinity="0"/>
          <site name="left_upper_arm" class="touch" pos="0 0 -0.14" size="0.046 0.1" zaxis="0 0 1"/>

          <body name="left_lower_arm" pos="0 -0.0460178 -0.260974" quat="0.996195 -0.0871577 0 0">
            <inertial pos="0.00233075 -0.00156548 -0.216552" quat="0.876335 -0.0179255 0.0050715 0.481342" mass="0.62762" diaginertia="0.00881688 0.00874569 0.000546268"/>
            <joint name="left_elbow" axis="0 1 0" range="-160 0" stiffness="150" damping="15" armature=".015"/>
            <!-- <geom name="left_lower_arm" fromto="0 0 -0.0525 0 0 -0.1875" size="0.04" density="1056"/> -->
            <geom name="left_lower_arm1" type="mesh" rgba="1 1 1 1" mesh="left_elbow_pitch_link"/>
            <geom name="left_lower_arm2" pos="0 0 -0.151" quat="1 0 0 0" type="mesh" rgba="1 1 1 1" mesh="left_elbow_yaw_link"/>
            <geom name="left_lower_arm3" pos="0 0 -0.151" quat="1 3.8455e-05 0 0" type="mesh" rgba="1 1 1 1" mesh="left_elbow_roll_link"/>
            <geom name="left_lower_arm1_vis" type="mesh" rgba="1 1 1 1" mesh="left_elbow_pitch_link" contype="0" conaffinity="0"/>
            <geom name="left_lower_arm2_vis" pos="0 0 -0.151" quat="1 0 0 0" type="mesh" rgba="1 1 1 1" mesh="left_elbow_yaw_link" contype="0" conaffinity="0"/>
            <geom name="left_lower_arm3_vis" pos="0 0 -0.151" quat="1 3.8455e-05 0 0" type="mesh" rgba="1 1 1 1" mesh="left_elbow_roll_link" contype="0" conaffinity="0"/>
            <site name="left_lower_arm" class="touch" pos="0 0 -0.1" size="0.041 0.0685" zaxis="0 0 1"/>

            <body name="left_hand" pos="0 0 -0.235">
              <inertial pos="0 0 0" quat="0.518356 0.00509404 -0.0175802 0.854969" mass="0.31" diaginertia="0.000774 0.00082 0.0002681"/>
              <!-- <geom name="left_hand" type="sphere" size=".04" density="1865"/> -->
              <geom name="left_hand" pos="0 0 0" quat="1 0 0 0" type="mesh" rgba="1 1 1 1" mesh="left_wrist_pitch_link"/>
              <geom name="left_hand_vis" pos="0 0 0" quat="1 0 0 0" type="mesh" rgba="1 1 1 1" mesh="left_wrist_pitch_link" contype="0" conaffinity="0"/>
              <site name="left_hand" class="touch" type="sphere" size=".041"/>
            </body>
          </body>
        </body>
      </body>

      <body name="right_thigh" pos="0 -0.11 0.1">
        <inertial pos="0 0 -0.234702" quat="0.706767 -0.020703 0.0207096 0.70684" mass="8.816596" diaginertia="0.0533988 0.0514009 0.0162939"/>
        <site name="right_hip" class="force-torque"/>
        <joint name="right_hip_x" pos="0 0 -0.08" axis="1 0 0" range="-60 15" stiffness="300" damping="30" armature=".02"/>
        <joint name="right_hip_y" pos="0 0 -0.08" axis="0 1 0" range="-140 60" stiffness="300" damping="30" armature=".02"/>
        <joint name="right_hip_z" pos="0 0 -0.08" axis="0 0 1" range="-60 35" stiffness="300" damping="30" armature=".02"/>
        <!-- <geom name="right_thigh" fromto="0 0 -0.06 0 0 -0.36" size="0.055" density="1269"/> -->
        <geom name="right_thigh1" type="mesh" pos="0 -0.008 -0.08" rgba="1 1 1 1" mesh="right_hip_pitch_link"/>
        <geom name="right_thigh2" type="mesh" rgba="1 1 1 1" pos="0 -0.008 -0.08" mesh="right_hip_roll_link"/>
        <geom name="right_thigh3" type="mesh" pos="0 -0.008 -0.08" quat="0.707105 0 0 0.707108" rgba="1 1 1 1" mesh="right_hip_yaw_link"/>
        <geom name="right_thigh1_vis" type="mesh" pos="0 -0.008 -0.08" rgba="1 1 1 1" mesh="right_hip_pitch_link" contype="0" conaffinity="0"/>
        <geom name="right_thigh2_vis" type="mesh" rgba="1 1 1 1" pos="0 -0.008 -0.08" mesh="right_hip_roll_link" contype="0" conaffinity="0"/>
        <geom name="right_thigh3_vis" type="mesh" pos="0 -0.008 -0.08" quat="0.707105 0 0 0.707108" rgba="1 1 1 1" mesh="right_hip_yaw_link" contype="0" conaffinity="0"/>
        <site name="right_thigh" class="touch" pos="0 0 -0.21" size="0.056 0.301" zaxis="0 0 -1"/>

        <body name="right_shin" pos="0 0 -0.49">
          <inertial pos="0.00163174 -3.06908e-05 -0.203316" quat="0.996251 -3.6809e-05 0.086509 -6.0467e-05" mass="4.74475" diaginertia="0.0526845 0.0511884 0.00647413"/>
          <site name="right_knee" class="force-torque" pos="0 0 .02"/>
          <joint name="right_knee" pos="0 0 0" axis="0 1 0" range="0 160" stiffness="300" damping="30" armature=".02"/>
          <!-- <geom name="right_shin" fromto="0 0 -0.045 0 0 -0.355"  size=".05" density="1014"/> -->
          <geom name="right_knee" type="mesh" rgba="1 1 1 1" mesh="right_knee_link"/>
          <geom name="right_knee_vis" type="mesh" rgba="1 1 1 1" mesh="right_knee_link" contype="0" conaffinity="0"/>
          <site name="right_shin" class="touch" pos="0 0 -0.2" size="0.051 0.156" zaxis="0 0 -1"/>

          <body name="right_foot" pos="0 0 -0.41">
            <inertial pos="0.0629575 -4.51202e-06 -0.0468493" quat="2.53009e-05 0.666884 -3.04817e-05 0.745162" mass="1.4" diaginertia="0.00933838 0.00859547 0.00157442"/>
            <site name="right_ankle" class="force-torque"/>
            <joint name="right_ankle_x" pos="0 0 -0.0275" axis="1 0 0" range="-30 30" stiffness="200" damping="20" armature=".01"/>
            <joint name="right_ankle_y" pos="0 0 -0.0275" axis="0 1 0" range="-85 85" stiffness="150" damping="20" armature=".01"/><!--350 backflip  150 walk run 300雷런로-->
            <joint name="right_ankle_z" pos="0 0 -0.0275" axis="0 0 1" range="-40 40" stiffness="200" damping="20" armature=".01"/>
            <!-- <geom name="right_foot" type="box" pos="0.045 0 -0.05" size="0.0885 0.045 0.0275"/>-->
            <!-- <geom type="mesh" rgba="1 1 1 1" mesh="right_ankle_pitch_link"/> -->
            <!-- <geom name="right_foot" type="mesh" rgba="1 1 1 1" mesh="right_ankle_roll_link"/>  -->
            <geom name="right_foot" type="box" pos="0.01 0 -0.05" size="0.11 0.045 0.0275"/>
            <geom name="right_foot_vis" type="mesh" rgba="1 1 1 1" mesh="right_ankle_roll_link" contype="0" conaffinity="0"/> 
            <site name="right_foot" class="touch" type="box" pos="0.045 0 -0.0225" size="0.0895 0.055 0.0285"/>
          </body>
        </body>
      </body>

      <body name="left_thigh" pos="0 0.11 0.1">
        <inertial pos="0 0 -0.234702" quat="0.706767 -0.020703 0.0207096 0.70684" mass="8.816596" diaginertia="0.0533988 0.0514009 0.0162939"/>
        <site name="left_hip" class="force-torque"/>
        <joint name="left_hip_x" axis="1 0 0" pos="0 0 -0.08" range="-15 60" stiffness="300" damping="30" armature=".02"/>
        <joint name="left_hip_y" axis="0 1 0" pos="0 0 -0.08" range="-140 60" stiffness="300" damping="30" armature=".02"/>
        <joint name="left_hip_z" axis="0 0 1" pos="0 0 -0.08" range="-35 60" stiffness="300" damping="30" armature=".02"/>
        <!-- <geom name="left_thigh" fromto="0 0 -0.06 0 0 -0.36" size=".055" density="1269"/> -->
        <geom name="left_thigh1" type="mesh" pos="0 0.008 -0.08" rgba="1 1 1 1" mesh="left_hip_pitch_link"/>
        <geom name="left_thigh2" type="mesh" rgba="1 1 1 1" pos="0 0.008 -0.08" mesh="left_hip_roll_link"/>
        <geom name="left_thigh3" type="mesh" pos="0 0.008 -0.08" quat="0.707105 0 0 0.707108" rgba="1 1 1 1" mesh="left_hip_yaw_link"/>
        <geom name="left_thigh1_vis" type="mesh" pos="0 0.008 -0.08" rgba="1 1 1 1" mesh="left_hip_pitch_link" contype="0" conaffinity="0"/>
        <geom name="left_thigh2_vis" type="mesh" rgba="1 1 1 1" pos="0 0.008 -0.08" mesh="left_hip_roll_link" contype="0" conaffinity="0"/>
        <geom name="left_thigh3_vis" type="mesh" pos="0 0.008 -0.08" quat="0.707105 0 0 0.707108" rgba="1 1 1 1" mesh="left_hip_yaw_link" contype="0" conaffinity="0"/>
        <site name="left_thigh" class="touch" pos="0 0 -0.21" size="0.056 0.301" zaxis="0 0 -1"/>

        <body name="left_shin" pos="0 0 -0.49">
          <inertial pos="0.00163174 -3.06908e-05 -0.203316" quat="0.996251 -3.6809e-05 0.086509 -6.0467e-05" mass="4.74475" diaginertia="0.0526845 0.0511884 0.00647413"/>
          <site name="left_knee" class="force-torque" pos="0 0 .02"/>
          <joint name="left_knee" pos="0 0 0" axis="0 1 0" range="0 160" stiffness="300" damping="30" armature=".02"/>
          <!-- <geom name="left_shin" fromto="0 0 -0.045 0 0 -0.355"  size=".05" density="1014"/> -->
          <geom name="left_knee" type="mesh" rgba="1 1 1 1" mesh="left_knee_link"/>
          <geom name="left_knee_vis" type="mesh" rgba="1 1 1 1" mesh="left_knee_link" contype="0" conaffinity="0"/>
          <site name="left_shin" class="touch" pos="0 0 -0.2" size="0.051 0.156" zaxis="0 0 -1"/>

          <body name="left_foot" pos="0 0 -0.41">
            <inertial pos="0.062957 4.80199e-06 -0.0468493" quat="-3.21756e-05 0.666884 2.31797e-05 0.745161" mass="1.4" diaginertia="0.00933838 0.00859548 0.00157441"/>
            <site name="left_ankle" class="force-torque"/>
            <joint name="left_ankle_x" pos="0 0 -0.0275" axis="1 0 0" range="-30 30" stiffness="200" damping="20" armature=".01"/>
            <joint name="left_ankle_y" pos="0 0 -0.0275" axis="0 1 0" range="-85 85" stiffness="150" damping="20" armature=".01"/><!--350 backflip 150 walk run 300雷런로-->
            <joint name="left_ankle_z" pos="0 0 -0.0275" axis="0 0 1" range="-40 40" stiffness="200" damping="20" armature=".01"/>
            <!--<geom name="left_foot" type="box" pos="0.045 0 -0.05" size="0.0885 0.045 0.0275"/>  walk :stiffness= 120 damping= 10-->
            <!-- <geom type="mesh" rgba="1 1 1 1" mesh="left_ankle_pitch_link"/> -->
            <!-- <geom name="left_foot" type="mesh" rgba="1 1 1 1" mesh="left_ankle_roll_link"/> -->
            <geom name="left_foot" type="box" pos="0.01 0 -0.05" size="0.1 0.045 0.0275"/>
            <geom name="left_foot_vis" type="mesh" rgba="1 1 1 1" mesh="left_ankle_roll_link" contype="0" conaffinity="0"/>
            <site name="left_foot" class="touch" type="box" pos="0.045 0 -0.0225" size="0.0895 0.055 0.0285"/>
          </body>
        </body>
      </body>
    </body>
  </worldbody>

  <actuator>
    <motor name='abdomen_x'       gear='125' joint='abdomen_x'/>
    <motor name='abdomen_y'       gear='125' joint='abdomen_y'/>
    <motor name='abdomen_z'       gear='125' joint='abdomen_z'/>
    <motor name='neck_x'          gear='20' joint='neck_x'/>
    <motor name='neck_y'          gear='20' joint='neck_y'/>
    <motor name='neck_z'          gear='20' joint='neck_z'/>
    <motor name='right_shoulder_x' gear='70' joint='right_shoulder_x'/>
    <motor name='right_shoulder_y' gear='70' joint='right_shoulder_y'/>
    <motor name='right_shoulder_z' gear='70' joint='right_shoulder_z'/>
    <motor name='right_elbow'     gear='60' joint='right_elbow'/>
    <motor name='left_shoulder_x'  gear='70' joint='left_shoulder_x'/>
    <motor name='left_shoulder_y'  gear='70' joint='left_shoulder_y'/>
    <motor name='left_shoulder_z'  gear='70' joint='left_shoulder_z'/>
    <motor name='left_elbow'      gear='60' joint='left_elbow'/>
    <motor name='right_hip_x'     gear='125' joint='right_hip_x'/>
    <motor name='right_hip_z'     gear='125' joint='right_hip_z'/>
    <motor name='right_hip_y'     gear='125' joint='right_hip_y'/>
    <motor name='right_knee'      gear='100' joint='right_knee'/>
    <motor name='right_ankle_x'   gear='50' joint='right_ankle_x'/>
    <motor name='right_ankle_y'   gear='50' joint='right_ankle_y'/>
    <motor name='right_ankle_z'   gear='50' joint='right_ankle_z'/>
    <motor name='left_hip_x'      gear='125' joint='left_hip_x'/>
    <motor name='left_hip_z'      gear='125' joint='left_hip_z'/>
    <motor name='left_hip_y'      gear='125' joint='left_hip_y'/>
    <motor name='left_knee'       gear='100' joint='left_knee'/>
    <motor name='left_ankle_x'    gear='50' joint='left_ankle_x'/>
    <motor name='left_ankle_y'    gear='50' joint='left_ankle_y'/>
    <motor name='left_ankle_z'    gear='50' joint='left_ankle_z'/>
  </actuator>

  <!-- <sensor>
    <subtreelinvel name="pelvis_subtreelinvel" body="pelvis"/>
    <accelerometer name="root_accel"    site="root"/>
    <velocimeter name="root_vel"        site="root"/>
    <gyro name="root_gyro"              site="root"/>

    <force name="left_ankle_force"       site="left_ankle"/>
    <force name="right_ankle_force"      site="right_ankle"/>
    <force name="left_knee_force"        site="left_knee"/>
    <force name="right_knee_force"       site="right_knee"/>
    <force name="left_hip_force"         site="left_hip"/>
    <force name="right_hip_force"        site="right_hip"/>

    <torque name="left_ankle_torque"     site="left_ankle"/>
    <torque name="right_ankle_torque"    site="right_ankle"/>
    <torque name="left_knee_torque"      site="left_knee"/>
    <torque name="right_knee_torque"     site="right_knee"/>
    <torque name="left_hip_torque"       site="left_hip"/>
    <torque name="right_hip_torque"      site="right_hip"/>

    <touch name="pelvis_touch"           site="pelvis"/>
    <touch name="upper_waist_touch"      site="upper_waist"/>
    <touch name="torso_touch"            site="torso"/>
    <touch name="head_touch"             site="head"/>
    <touch name="right_upper_arm_touch"  site="right_upper_arm"/>
    <touch name="right_lower_arm_touch"  site="right_lower_arm"/>
    <touch name="right_hand_touch"       site="right_hand"/>
    <touch name="left_upper_arm_touch"   site="left_upper_arm"/>
    <touch name="left_lower_arm_touch"   site="left_lower_arm"/>
    <touch name="left_hand_touch"        site="left_hand"/>
    <touch name="right_thigh_touch"      site="right_thigh"/>
    <touch name="right_shin_touch"       site="right_shin"/>
    <touch name="right_foot_touch"       site="right_foot"/>
    <touch name="left_thigh_touch"       site="left_thigh"/>
    <touch name="left_shin_touch"        site="left_shin"/>
    <touch name="left_foot_touch"        site="left_foot"/>
  </sensor> -->

</mujoco>
